<?xml version="1.0"?>
<robot name="fishbot">


    
  <!-- base link -->
  <link name="base_link">
      <visual>
      <origin xyz="0 0 0.0" rpy="0 0 0"/>
      <geometry>
        <box size="0.29 0.29 0.02"/>
      </geometry>
      <material name = "White">
        <color rgba="1.0 1.0 1.0 0.8"/>
      </material>
    </visual>
    <collision>
      <origin xyz="0 0 0" rpy="0 0 0"/>
      <geometry>
        <box size="0.29 0.29 0.02"/>
      </geometry>
    </collision>
    <inertial>
      <mass value="0.8"/>
      <inertia ixx="0.005633333" ixy="0.0" ixz="0.0" iyy="0.011213333" iyz="0.0" izz="0.005633333"/>
    </inertial>
  </link>


  
  <!-- pillar_link1 -->
  <link name="pillar_link1">
    <visual>
        <origin xyz="0.0 0.0 0.0" rpy="0.0 0.0 0.0"/>
        <geometry>
            <box size="0.02 0.02 0.5"/> 
        </geometry>
        <material name = "White">
            <color rgba="1.0 1.0 1.0 0.8"/>
        </material>
    </visual>
    <collision>
      <origin xyz="0 0 0" rpy="0 0 0"/>
      <geometry>
        <box size="0.02 0.02 0.5"/>
      </geometry>
    </collision>
    <inertial>
    <mass value="0.285875"/>
      <inertia ixx="0.005965258" ixy="0.0" ixz="0.0" iyy="0.000019058" iyz="0.0" izz="0.005965258"/>
    </inertial>
  </link>

  <joint name="pillar_joint1" type="fixed">
    <parent link="base_link" />
    <child link="pillar_link1" />
    <origin xyz="0.135 0.135 0.26" />
    <axis xyz="0 0 0" />
  </joint>
    
  <link name="pillar_link2">
    <visual>
        <origin xyz="0.0 0.0 0.0" rpy="0.0 0.0 0.0"/>
        <geometry>
            <box size="0.02 0.02 0.5"/> 
        </geometry>
        <material name = "White">
            <color rgba="1.0 1.0 1.0 0.8"/>
        </material>
    </visual>
    <collision>
      <origin xyz="0 0 0" rpy="0 0 0"/>
      <geometry>
        <box size="0.02 0.02 0.5"/>
      </geometry>
    </collision>
    <inertial>
    <mass value="0.285875"/>
      <inertia ixx="0.005965258" ixy="0.0" ixz="0.0" iyy="0.000019058" iyz="0.0" izz="0.005965258"/>
    </inertial>
  </link>

  <joint name="pillar_joint2" type="fixed">
    <parent link="base_link" />
    <child link="pillar_link2" />
    <origin xyz="-0.135 0.135 0.26" />
    <axis xyz="0 0 0" />
  </joint>

  <link name="pillar_link3">
    <visual>
        <origin xyz="0.0 0.0 0.0" rpy="0.0 0.0 0.0"/>
        <geometry>
            <box size="0.02 0.02 0.5"/> 
        </geometry>
        <material name = "White">
            <color rgba="1.0 1.0 1.0 0.8"/>
        </material>
    </visual>
    <collision>
      <origin xyz="0 0 0" rpy="0 0 0"/>
      <geometry>
        <box size="0.02 0.02 0.5"/>
      </geometry>
    </collision>
    <inertial>
    <mass value="0.285875"/>
      <inertia ixx="0.005965258" ixy="0.0" ixz="0.0" iyy="0.000019058" iyz="0.0" izz="0.005965258"/>
    </inertial>
  </link>

  <joint name="pillar_joint3" type="fixed">
    <parent link="base_link" />
    <child link="pillar_link3" />
    <origin xyz="0.135 -0.135 0.26" />
    <axis xyz="0 0 0" />
  </joint>

  <link name="pillar_link4">
    <visual>
        <origin xyz="0.0 0.0 0.0" rpy="0.0 0.0 0.0"/>
        <geometry>
            <box size="0.02 0.02 0.5"/> 
        </geometry>
        <material name = "White">
            <color rgba="1.0 1.0 1.0 0.8"/>
        </material>
    </visual>
    <collision>
      <origin xyz="0 0 0" rpy="0 0 0"/>
      <geometry>
        <box size="0.02 0.02 0.5"/>
      </geometry>
    </collision>
    <inertial>
      <mass value="0.285875"/>
      <inertia ixx="0.005965258" ixy="0.0" ixz="0.0" iyy="0.000019058" iyz="0.0" izz="0.005965258"/>
    </inertial>
  </link>

  <joint name="pillar_joint4" type="fixed">
    <parent link="base_link" />
    <child link="pillar_link4" />
    <origin xyz="-0.135 -0.135 0.26" />
    <axis xyz="0 0 0" />
  </joint>
  


  <!-- platform_links -->
  <link name="platform_link">
    <visual>
        <origin xyz="0.0 0.0 0.0" rpy="0.0 0.0 0.0"/>
        <geometry>
            <box size="0.29 0.29 0.02"/>
        </geometry>
        <material name = "White">
            <color rgba="1.0 1.0 1.0 0.8"/>
        </material>
    </visual>
    <collision>
      <origin xyz="0 0 0" rpy="0 0 0"/>
      <geometry>
        <box size="0.29 0.29 0.02"/>
      </geometry>
    </collision>
    <inertial>
      <mass value="0.8"/>
      <inertia ixx="0.005633333" ixy="0.0" ixz="0.0" iyy="0.011213333" iyz="0.0" izz="0.005633333"/>
    </inertial>
  </link>

  <joint name="platform_joint" type="fixed">
    <parent link="base_link" />
    <child link="platform_link" />
    <origin xyz="0 0 0.13" />
    <axis xyz="0 0 0" />
  </joint>

  <link name="uplatform_link">
    <visual>
        <origin xyz="0.0 0.0 0.0" rpy="0.0 0.0 0.0"/>
        <geometry>
            <box size="0.29 0.29 0.02"/>
        </geometry>
        <material name = "White">
            <color rgba="1.0 1.0 1.0 0.8"/>
        </material>
    </visual>
    <collision>
      <origin xyz="0 0 0" rpy="0 0 0"/>
      <geometry>
        <box size="0.29 0.29 0.02"/>
      </geometry>
    </collision>
    <inertial>
      <mass value="0.8"/>
      <inertia ixx="0.005633333" ixy="0.0" ixz="0.0" iyy="0.011213333" iyz="0.0" izz="0.005633333"/>
    </inertial>
  </link>

  <joint name="uplatform_joint" type="fixed">
    <parent link="base_link" />
    <child link="uplatform_link" />
    <origin xyz="0 0 0.5" />
    <axis xyz="0 0 0" />
  </joint>




  <!-- laser link -->
  <link name="laser_link">
      <visual>
      <origin xyz="0 0 0" rpy="0 0 0"/>
      <geometry>
        <cylinder length="0.026" radius="0.038"/>
      </geometry>
      <material name="black">
          <color rgba="0.0 0.0 0.0 0.8" /> 
      </material>
    </visual>
    <collision>
      <origin xyz="0 0 0" rpy="0 0 0"/>
      <geometry>
        <cylinder length="0.026" radius="0.038"/>
      </geometry>
    </collision>
    <inertial>
      <mass value="0.2"/>
      <inertia ixx="0.000054067" ixy="0.0" ixz="0.0" iyy="0.000054067" iyz="0.0" izz="0.0000625"/>
    </inertial>
  </link>

  <joint name="laser_joint" type="fixed">
    <parent link="platform_link" />
    <child link="laser_link" />
    <origin xyz="0 0 0.05" />
  </joint>



   <!-- motor_links -->
  <link name="motor_link1">
    <visual>
    <origin xyz="0.0 0.0 0.0" rpy="0.0 0.0 0.0"/>
    <geometry>
        <box size="0.05 0.05 0.05"/>
    </geometry>
    <material name="purple">
        <color rgba="1.0 0.0 1.0 0.8"/>
    </material>
    </visual>
    <collision>
      <origin xyz="0 0 0" rpy="0 0 0"/>
      <geometry>
        <box size="0.05 0.05 0.05"/>
      </geometry>
    </collision>
    <inertial>
      <mass value="0.3"/>
      <inertia ixx="0.000125" ixy="0.0" ixz="0.0" iyy="0.000125" iyz="0.0" izz="0.000125"/>
    </inertial>
  </link>

  <joint name="motor_joint1" type="fixed">
    <parent link="base_link"/>
    <child link="motor_link1"/>
    <origin xyz="0.09 0.135 -0.035"/>
  </joint>

  <link name="motor_link2">
    <visual>
    <origin xyz="0.0 0.0 0.0" rpy="0.0 0.0 0.0"/>
    <geometry>
        <box size="0.05 0.05 0.05"/>
    </geometry>
    <material name="purple">
        <color rgba="1.0 0.0 1.0 0.8"/>
    </material>
    </visual>
    <collision>
      <origin xyz="0 0 0" rpy="0 0 0"/>
      <geometry>
        <box size="0.05 0.05 0.05"/>
      </geometry>
    </collision>
    <inertial>
      <mass value="0.3"/>
      <inertia ixx="0.000125" ixy="0.0" ixz="0.0" iyy="0.000125" iyz="0.0" izz="0.000125"/>
    </inertial>
  </link>

  <joint name="motor_joint2" type="fixed">
    <parent link="base_link"/>
    <child link="motor_link2"/>
    <origin xyz="-0.09 0.135 -0.035"/>
  </joint>

  <link name="motor_link3">
    <visual>
    <origin xyz="0.0 0.0 0.0" rpy="0.0 0.0 0.0"/>
    <geometry>
        <box size="0.05 0.05 0.05"/>
    </geometry>
    <material name="purple">
        <color rgba="1.0 0.0 1.0 0.8"/>
    </material>
    </visual>
    <collision>
      <origin xyz="0 0 0" rpy="0 0 0"/>
      <geometry>
        <box size="0.05 0.05 0.05"/>
      </geometry>
    </collision>
    <inertial>
      <mass value="0.3"/>
      <inertia ixx="0.000125" ixy="0.0" ixz="0.0" iyy="0.000125" iyz="0.0" izz="0.000125"/>
    </inertial>
  </link>

  <joint name="motor_joint3" type="fixed">
    <parent link="base_link"/>
    <child link="motor_link3"/>
    <origin xyz="0.09 -0.135 -0.035"/>
  </joint>

  <link name="motor_link4">
    <visual>
    <origin xyz="0.0 0.0 0.0" rpy="0.0 0.0 0.0"/>
    <geometry>
        <box size="0.05 0.05 0.05"/>
    </geometry>
    <material name="purple">
        <color rgba="1.0 0.0 1.0 0.8"/>
    </material>
    </visual>
    <collision>
      <origin xyz="0 0 0" rpy="0 0 0"/>
      <geometry>
        <box size="0.05 0.05 0.05"/>
      </geometry>
    </collision>
    <inertial>
      <mass value="0.3"/>
      <inertia ixx="0.000125" ixy="0.0" ixz="0.0" iyy="0.000125" iyz="0.0" izz="0.000125"/>
    </inertial>
  </link>

  <joint name="motor_joint4" type="fixed">
    <parent link="base_link"/>
    <child link="motor_link4"/>
    <origin xyz="-0.09 -0.135 -0.035"/>
  </joint>



  <!-- wheel_links -->
  <link name="wheel_link1">
    <visual>
    <origin xyz="0.0 0.0 0.0" rpy="1.57079 0.0 0.0"/>
    <geometry>
      <cylinder length="0.05" radius="0.065"/>
    </geometry>
    <material name="black">
      <color rgba="0.0 0.0 0.0 0.8"/> 
    </material>
    </visual>
    <collision>
      <origin xyz="0 0 0" rpy = "1.57079 0 0"/>
      <geometry>
        <cylinder length="0.05" radius="0.065"/>
      </geometry>
    </collision>
    <inertial>
      <mass value="0.24"/>
      <inertia ixx="0.000284375" ixy="0.0" ixz="0.0" iyy="0.000284375" iyz="0.0" izz="0.046875"/>
    </inertial>
  </link>

  <joint name="wheel_joint1" type="continuous">
    <parent link="motor_link1"/>
    <child link="wheel_link1"/>
    <origin xyz="0.0 0.05 0.0"/>
    <axis xyz="0.0 1.0 0.0"/>
  </joint>

  <link name="wheel_link2">
    <visual>
    <origin xyz="0.0 0.0 0.0" rpy="1.57079 0.0 0.0"/>
    <geometry>
      <cylinder length="0.05" radius="0.065"/>
    </geometry>
    <material name="black">
      <color rgba="0.0 0.0 0.0 0.8"/> 
    </material>
    </visual>
    <collision>
      <origin xyz="0 0 0" rpy = "1.57079 0 0"/>
      <geometry>
        <cylinder length="0.05" radius="0.065"/>
      </geometry>
    </collision>
    <inertial>
      <mass value="0.24"/>
      <inertia ixx="0.000284375" ixy="0.0" ixz="0.0" iyy="0.000284375" iyz="0.0" izz="0.046875"/>
    </inertial>
  </link>

  <joint name="wheel_joint2" type="continuous">
    <parent link="motor_link2"/>
    <child link="wheel_link2"/>
    <origin xyz="0.0 0.05 0.0"/>
    <axis xyz="0.0 1.0 0.0"/>
  </joint>

  <link name="wheel_link3">
    <visual>
    <origin xyz="0.0 0.0 0.0" rpy="1.57079 0.0 0.0"/>
    <geometry>
      <cylinder length="0.05" radius="0.065"/>
    </geometry>
    <material name="black">
      <color rgba="0.0 0.0 0.0 0.8"/> 
    </material>
    </visual>
    <collision>
      <origin xyz="0 0 0" rpy = "1.57079 0 0"/>
      <geometry>
        <cylinder length="0.05" radius="0.065"/>
      </geometry>
    </collision>
    <inertial>
      <mass value="0.24"/>
      <inertia ixx="0.000284375" ixy="0.0" ixz="0.0" iyy="0.000284375" iyz="0.0" izz="0.046875"/>
    </inertial>
  </link>

  <joint name="wheel_joint3" type="continuous">
    <parent link="motor_link3"/>
    <child link="wheel_link3"/>
    <origin xyz="0.0 -0.05 0.0"/>
    <axis xyz="0.0 1.0 0.0"/>
  </joint>

  <link name="wheel_link4">
    <visual>
    <origin xyz="0.0 0.0 0.0" rpy="1.57079 0.0 0.0"/>
    <geometry>
      <cylinder length="0.05" radius="0.065"/>
    </geometry>
    <material name="black">
      <color rgba="0.0 0.0 0.0 0.8"/> 
    </material>
    </visual>
    <collision>
      <origin xyz="0 0 0" rpy = "1.57079 0 0"/>
      <geometry>
        <cylinder length="0.05" radius="0.065"/>
      </geometry>
    </collision>
    <inertial>
      <mass value="0.24"/>
      <inertia ixx="0.000284375" ixy="0.0" ixz="0.0" iyy="0.000284375" iyz="0.0" izz="0.046875"/>
    </inertial>
  </link>

  <joint name="wheel_joint4" type="continuous">
    <parent link="motor_link4"/>
    <child link="wheel_link4"/>
    <origin xyz="0.0 -0.05 0.0"/>
    <axis xyz="0.0 1.0 0.0"/>
  </joint>




  <!-- control_links -->
  <link name="control_link1">
    <visual>
    <origin xyz="0.0 0.0 0.0" rpy="0.0 0.0 0.0"/>
    <geometry>
      <box size="0.1 0.1 0.02"/>
    </geometry>
    <material name="green">
      <color rgba="0.0 1.0 0.0 0.8"/>
    </material>
    </visual>
    <collision>
      <origin xyz="0 0 0" rpy="0 0 0"/>
      <geometry>
        <box size="0.1 0.1 0.02"/>
      </geometry>
    </collision>
    <inertial>
      <mass value="0.3"/>
      <inertia ixx="0.00312" ixy="0.0" ixz="0.0" iyy="0.0005" iyz="0.0" izz="0.00312"/>
    </inertial>
  </link>

  <joint name="control_joint1" type="fixed">
    <origin xyz="0.0 0.0 0.02"/>
    <parent link="base_link"/>
    <child link="control_link1"/>
    <axis xyz="0.0 0.0 0.0"/>
  </joint>




  <!-- imu_link   -->
  <link name="imu_link">
    <visual>
      <origin xyz="0.0 0.0 0.0" rpy="0.0 0.0 0.0"/>
      <geometry>
        <box size="0.02 0.02 0.02"/>
      </geometry>
      <material name="green">
        <color rgba="0.0 1.0 0.0 0.8"/>
      </material>
    </visual>
     <collision>
      <origin xyz="0 0 0.0" rpy="0 0 0"/>
      <geometry>
		    <box size="0.01 0.01 0.002"/>
      </geometry>
    </collision>
    <inertial>
      <mass value="0.01"/>
        <inertia ixx="0.000000087" ixy="0" ixz="0" iyy="0.000000167" iyz="0" izz="0.000000087"/>
      </inertial>
  </link>

  <joint name="imu_joint" type="fixed">
    <origin xyz="0.0 0.0 0.02"/>
    <parent link="platform_link"/>
    <child link="imu_link"/>
    <axis xyz="0.0 0.0 0.0"/>
  </joint>



    <!-- Robot Footprint -->
  <link name="base_footprint"/>

  <joint name="base_joint" type="fixed">
    <parent link="base_footprint"/>
    <child link="base_link"/>
    <origin xyz="0.0 0.0 0.1125" rpy="0 0 0"/>
  </joint>









  <!-- gzaebo -->

  <gazebo>
      <plugin name='diff_drive' filename='libgazebo_ros_planar_move.so'>          
          <ros>
            <namespace>/</namespace>
            <remapping>cmd_vel:=cmd_vel</remapping>
            <remapping>odom:=odom</remapping>
          </ros>
          <update_rate>30</update_rate>
          <!-- wheels -->
          <leftFrontJoint>wheel_joint1</leftFrontJoint>
          <leftRearJoint>wheel_joint2</leftRearJoint>
          <rightFrontJoint>wheel_joint3</rightFrontJoint>
          <rightRearJoint>wheel_joint4</rightRearJoint>
          <!-- limits -->
          <max_wheel_torque>20</max_wheel_torque>
          <max_wheel_acceleration>1.0</max_wheel_acceleration>
          <!-- output -->
          <publish_odom>true</publish_odom>
          <publish_odom_tf>true</publish_odom_tf>
          <publish_wheel_tf>true</publish_wheel_tf>
          <odometry_frame>odom</odometry_frame>
          <robot_base_frame>base_footprint</robot_base_frame>
      </plugin>

      <plugin name = "fishbot_joint_state" filename="libgazebo_ros_joint_state_publisher.so">
        <ros>
          <remapping>~/out:=joint_states</remapping>
        </ros>
        <update_rate>30</update_rate>
        <joint_name>wheel_joint1</joint_name>
        <joint_name>wheel_joint2</joint_name>
        <joint_name>wheel_joint3</joint_name>
        <joint_name>wheel_joint4</joint_name>
      </plugin> 
  </gazebo>

  <gazebo reference="imu_link">
      <sensor name="imu_sensor" type="imu">
      <plugin filename="libgazebo_ros_imu_sensor.so" name="imu_plugin">
          <ros>
            <namespace>/</namespace>
            <remapping>~/out:=imu</remapping>
          </ros>
          <initial_orientation_as_reference>false</initial_orientation_as_reference>
        </plugin>
        <always_on>true</always_on>
        <update_rate>100</update_rate>
        <visualize>true</visualize>
        <imu>
          <angular_velocity>
            <x>
              <noise type="gaussian">
                <mean>0.0</mean>
                <stddev>2e-4</stddev>
                <bias_mean>0.0000075</bias_mean>
                <bias_stddev>0.0000008</bias_stddev>
              </noise>
            </x>
            <y>
              <noise type="gaussian">
                <mean>0.0</mean>
                <stddev>2e-4</stddev>
                <bias_mean>0.0000075</bias_mean>
                <bias_stddev>0.0000008</bias_stddev>
              </noise>
            </y>
            <z>
              <noise type="gaussian">
                <mean>0.0</mean>
                <stddev>2e-4</stddev>
                <bias_mean>0.0000075</bias_mean>
                <bias_stddev>0.0000008</bias_stddev>
              </noise>
            </z>
          </angular_velocity>
          <linear_acceleration>
            <x>
              <noise type="gaussian">
                <mean>0.0</mean>
                <stddev>1.7e-2</stddev>
                <bias_mean>0.1</bias_mean>
                <bias_stddev>0.001</bias_stddev>
              </noise>
            </x>
            <y>
              <noise type="gaussian">
                <mean>0.0</mean>
                <stddev>1.7e-2</stddev>
                <bias_mean>0.1</bias_mean>
                <bias_stddev>0.001</bias_stddev>
              </noise>
            </y>
            <z>
              <noise type="gaussian">
                <mean>0.0</mean>
                <stddev>1.7e-2</stddev>
                <bias_mean>0.1</bias_mean>
                <bias_stddev>0.001</bias_stddev>
              </noise>
            </z>
          </linear_acceleration>
        </imu>
      </sensor>
    </gazebo>

    <gazebo reference="laser_link">
      <sensor name="laser_sensor" type="ray">
      <always_on>true</always_on>
      <visualize>true</visualize>
      <update_rate>5</update_rate>
      <pose>0 0 0.15 0 0 0</pose>
      <ray>
          <scan>
            <horizontal>
              <samples>360</samples>
              <resolution>1.000000</resolution>
              <min_angle>0.000000</min_angle>
              <max_angle>6.280000</max_angle>
            </horizontal>
          </scan>
          <range>
            <min>0.10000</min>
            <max>11</max>
            <resolution>0.015000</resolution>
          </range>
          <noise>
            <type>gaussian</type>
            <mean>0.0</mean>
            <stddev>0.01</stddev>
          </noise>
      </ray>

      <plugin name="laserscan" filename="libgazebo_ros_ray_sensor.so">
        <ros>
          <!-- <namespace>/tb3</namespace> -->
          <remapping>~/out:=scan</remapping>
        </ros>
        <output_type>sensor_msgs/LaserScan</output_type>
        <frame_name>laser_link</frame_name>
      </plugin>
      </sensor>
    </gazebo>
</robot>



